Workbook

Sheet Dashboard
A1: VASU's Project Tracker - August 2026
A2: Generated: September 18, 2026
A4: KEY METRICS
A5: Total Projects | B5: =COUNTA(Projects!A2:A176) -> 175
A6: Completed | B6: =COUNTIF(Projects!H2:H176,"Completed") -> 113
A7: Active | B7: =COUNTIF(Projects!H2:H176,"Active") -> 34
A8: Completion Rate | B8: =B6/B5 -> 0.64571429
A9: Success Rate | B9: =(B5-COUNTIF(Projects!H2:H176,"Lost"))/B5 -> 0.86857143
A10: Avg Duration (Days) | B10: =AVERAGE(Projects!I2:I176) -> 133.08088
A11: Followups Due This Month | B11: 39

Sheet Overall Summary
A1: VASU's Tracker 2026 - Overall Summary
A2: As of: August 2026
A4: OVERALL PROJECT COUNTS
A5: Metric | B5: Count | C5: Formula Reference | D5: Percentage
A6: Total Projects | B6: =COUNTA(Projects!A2:A176) -> 175 | D6: =B6/B6 -> 1
A7: Total Allocations | B7: =COUNTIF(Projects!B2:B176,"Allocation") -> 87 | C7: By Type | D7: =B7/B6 -> 0.49714286
A8: Total Escalations | B8: =COUNTIF(Projects!B2:B176,"Escalation") -> 88 | C8: By Type | D8: =B8/B6 -> 0.50285714
A10: Total Completed | B10: =COUNTIF(Projects!H2:H176,"Completed") -> 113 | C10: By Status | D10: =B10/B6 -> 0.64571429
A11: Total Active | B11: =COUNTIF(Projects!H2:H176,"Active") -> 34 | C11: By Status | D11: =B11/B6 -> 0.19428571
A12: Total Yet to Start | B12: =COUNTIF(Projects!H2:H176,"Yet To Start") -> 5 | C12: By Status | D12: =B12/B6 -> 0.028571429
A13: Total Held Up | B13: =COUNTIF(Projects!H2:H176,"Held Up") -> 0 | C13: By Status | D13: =B13/B6 -> 0
A14: Total Lost | B14: =COUNTIF(Projects!H2:H176,"Lost") -> 23 | C14: By Status | D14: =B14/B6 -> 0.13142857
A16: KEY PERFORMANCE INDICATORS
A17: KPI | B17: Value | C17: Description
A18: Completion Rate | B18: =B10/B6 -> 0.64571429 | C18: Projects Completed / Total
A19: Success Rate | B19: =(B6-B14)/B6 -> 0.86857143 | C19: (Total - Lost) / Total
A20: Active Project % | B20: =B11/B6 -> 0.19428571 | C20: Active / Total Projects
A21: Avg Duration (Days) | B21: =AVERAGE(Projects!I2:I176) -> 133.08088 | C21: Avg completion time

Sheet Year on Year Analysis
A1: YEAR ON YEAR ANALYSIS & COMPARISON
A2: Same-period comparison through August 2026
A4: ANNUAL / YTD SUMMARY
A5: Year | B5: Period Covered | C5: Add Alloc | D5: Add Escal | E5: Total Additions | F5: Completed | G5: Lost | H5: Held Up | I5: Closing Balance | J5: Completion Rate | K5: Success Rate
A6: 2025 | B6: Jan-Dec | C6: 50 | D6: 63 | E6: 113 | F6: 60 | G6: 11 | H6: 0 | I6: 42 | J6: 0.53097345 | K6: 0.90265487
A7: 2026 | B7: Jan-Aug | C7: 32 | D7: 24 | E7: 56 | F7: 53 | G7: 12 | H7: 0 | I7: 33 | J7: 0.94642857 | K7: 0.78571429
A10: SAME-PERIOD YOY COMPARISON
A11: Metric | B11: 2025 Same Period | C11: 2026 Same Period | D11: Change | E11: Change %
A12: Total Additions | B12: 87 | C12: 56 | D12: -31 | E12: -0.35632184
A13: Completed | B13: 39 | C13: 53 | D13: 14 | E13: 0.35897436
A14: Lost | B14: 9 | C14: 12 | D14: 3 | E14: 0.33333333
A15: Held Up | B15: 0 | C15: 0 | D15: 0 | E15: 0
A16: Completion Rate | B16: 0.44827586 | C16: 0.94642857 | D16: 0.49815271 | E16: 1.1112637
A17: Open Pipeline | B17: 4 | C17: 39 | D17: 35 | E17: 8.75
A21: MANAGEMENT INSIGHTS
A22: 1 | B22: August 2026 portfolio has 175 tracked projects with 113 completed.
A23: 2 | B23: Same-period additions are down 35.6% versus last year; pipeline creation needs management focus.
A24: 3 | B24: Same-period completions are up 35.9%; delivery performance is improving.
A25: 4 | B25: Current completion rate is 64.6%; open pipeline is 39 projects.
A26: 5 | B26: 39 completed-client follow-ups are scheduled for this month to validate usage and capture issues.

Sheet Monthly Metrics
A1: Monthly Project Tracking - Opening & Closing Balance
A2: Logic: Closing = Opening + Additions - Completed - Lost - Held
A4: Month | B4: Opening | C4: Add Alloc | D4: Add Escal | E4: Total Add | F4: Completed | G4: Lost | H4: Held | I4: Net Change | J4: Closing
A5: 2025-01 | B5: 0 | C5: 8 | D5: 12 | E5: 20 | F5: 0 | G5: 0 | H5: 0 | I5: =E5-F5-G5-H5 -> 20 | J5: 20
A6: 2025-02 | B6: 20 | C6: 6 | D6: 5 | E6: 11 | F6: 0 | G6: 0 | H6: 0 | I6: =E6-F6-G6-H6 -> 11 | J6: 31
A7: 2025-03 | B7: 31 | C7: 7 | D7: 4 | E7: 11 | F7: 0 | G7: 0 | H7: 0 | I7: =E7-F7-G7-H7 -> 11 | J7: 42
A8: 2025-04 | B8: 42 | C8: 2 | D8: 7 | E8: 9 | F8: 15 | G8: 1 | H8: 0 | I8: =E8-F8-G8-H8 -> -7 | J8: 35
A9: 2025-05 | B9: 35 | C9: 2 | D9: 4 | E9: 6 | F9: 2 | G9: 0 | H9: 0 | I9: =E9-F9-G9-H9 -> 4 | J9: 39
A10: 2025-06 | B10: 39 | C10: 7 | D10: 4 | E10: 11 | F10: 6 | G10: 3 | H10: 0 | I10: =E10-F10-G10-H10 -> 2 | J10: 41
A11: 2025-07 | B11: 41 | C11: 0 | D11: 7 | E11: 7 | F11: 9 | G11: 5 | H11: 0 | I11: =E11-F11-G11-H11 -> -7 | J11: 34
A12: 2025-08 | B12: 34 | C12: 5 | D12: 7 | E12: 12 | F12: 7 | G12: 0 | H12: 0 | I12: =E12-F12-G12-H12 -> 5 | J12: 39
A13: 2025-09 | B13: 39 | C13: 4 | D13: 3 | E13: 7 | F13: 3 | G13: 0 | H13: 0 | I13: =E13-F13-G13-H13 -> 4 | J13: 43
A14: 2025-10 | B14: 43 | C14: 3 | D14: 4 | E14: 7 | F14: 16 | G14: 1 | H14: 0 | I14: =E14-F14-G14-H14 -> -10 | J14: 33
A15: 2025-11 | B15: 33 | C15: 5 | D15: 5 | E15: 10 | F15: 2 | G15: 1 | H15: 0 | I15: =E15-F15-G15-H15 -> 7 | J15: 40
A16: 2025-12 | B16: 40 | C16: 1 | D16: 1 | E16: 2 | F16: 0 | G16: 0 | H16: 0 | I16: =E16-F16-G16-H16 -> 2 | J16: 42
... A25: 2026-09 | B25: 33 | C25: 5 | D25: 1 | E25: 6 | F25: 0 | G25: 0 | H25: 0 | I25: =E25-F25-G25-H25 -> 6 | J25: 39
A26: TOTAL | C26: =SUM(C5:C25) -> 87 | D26: =SUM(D5:D25) -> 88 | E26: =SUM(E5:E25) -> 175 | F26: =SUM(F5:F25) -> 113 | G26: =SUM(G5:G25) -> 23 | H26: =SUM(H5:H25) -> 0 | I26: =SUM(I5:I25) -> 39

Sheet Latest Month
A1: Latest Month Performance - 2026-08
A3: MONTH SUMMARY
A4: Metric | B4: Value | C4: Details
A5: Month | B5: '2026-08
A6: Opening Balance | B6: 33 | C6: Projects at start of month
A7: New Allocations | B7: 4 | C7: New allocation projects
A8: New Escalations | B8: 1 | C8: New escalation projects
A9: Total Additions | B9: 5 | C9: Total new projects
A10: Completed | B10: 2 | C10: Projects completed this month
A11: Lost | B11: 3 | C11: Projects lost this month
A12: Held Up | B12: 0 | C12: Projects held this month
A13: Net Change | B13: 0 | C13: Add - Comp - Lost - Held
A14: Closing Balance | B14: 33 | C14: Projects at end of month

Sheet Projects
A1: Project Code | B1: Project Type | C1: Project Name | D1: Received From | E1: Start Date | F1: End Date | G1: Priority | H1: Status | I1: Duration
A2: 5001 | B2: Allocation | C2: TARASAFE INTERNATIONAL PRIVATE LIMITED_STAFF | D2: Schedule | E2: 45664 | F2: 45958 | G2: Low | H2: Completed | I2: =IF(F2="","",F2-E2) -> 294
A3: 5002 | B3: Allocation | C3: TARASAFE INTERNATIONAL PRIVATE LIMITED_WORKER | D3: Schedule | E3: 45664 | F3: 45855 | G3: Low | H3: Lost | I3: =IF(F3="","",F3-E3) -> 191
A4: 5003 | B4: Escalation | C4: Maharashtra Book Manufacturing | D4: Schedule | E4: 45664 | F4: 45772 | G4: Low | H4: Completed | I4: =IF(F4="","",F4-E4) -> 108
A5: 5004 | B5: Escalation | C5: PLASMA RESEARCH TRUST NX | D5: Schedule | E5: 45664 | F5: 45772 | G5: Low | H5: Completed | I5: =IF(F5="","",F5-E5) -> 108
A6: 5005 | B6: Allocation | C6: Bengal Energy_Staff | D6: Schedule | E6: 45665 | F6: 46111 | G6: Low | H6: Completed | I6: =IF(F6="","",F6-E6) -> 446
A7: 5006 | B7: Allocation | C7: Bengal Energy_Worker | D7: Schedule | E7: 45665 | F7: 45838 | G7: Low | H7: Lost | I7: =IF(F7="","",F7-E7) -> 173
A8: 5007 | B8: Allocation | C8: Parbhani Medical College | D8: Schedule | E8: 45670 | F8: 46050 | G8: Low | H8: Lost | I8: =IF(F8="","",F8-E8) -> 380
A9: 5008 | B9: Escalation | C9: Aquaair International Frieght Services | D9: Schedule | E9: 45670 | F9: 45772 | G9: Low | H9: Completed | I9: =IF(F9="","",F9-E9) -> 102
A10: 5009 | B10: Escalation | C10: Hardcarb Technologies Private Limited | D10: Maketing | E10: 45671 | F10: 45772 | G10: Low | H10: Completed | I10: =IF(F10="","",F10-E10) -> 101
A11: 5010 | B11: Allocation | C11: MADHUSUMAN ENTERPRISES (MSE) HVAC SERVICES INDIA | D11: Schedule | E11: 45671 | F11: 45855 | G11: Low | H11: Completed | I11: =IF(F11="","",F11-E11) -> 184
A12: 5011 | B12: Allocation | C12: YUVA PARIVARTAN KHERWADI SOCIAL WELFARE ASSOCIATION | D12: Schedule | E12: 45671 | F12: 45958 | G12: Low | H12: Completed | I12: =IF(F12="","",F12-E12) -> 287
A13: 5012 | B13: Escalation | C13: GCOM SYSTEMS AND SOLUTIONS (OUR LADY OF SALVATION) | D13: Schedule | E13: 45671 | F13: 45772 | G13: Low | H13: Completed | I13: =IF(F13="","",F13-E13) -> 101
... A42: 5041 | B42: Escalation | C42: TATARIA HARDWARE INNOVATION | D42: Schedule | E42: 45734 | F42: 45809 | G42: Low | H42: Completed | I42: =IF(F42="","",F42-E42) -> 75
A43: 5042 | B43: Escalation | C43: THE NATIONAL SPORTS CLUB OF INDIA | D43: Schedule | E43: 45735 | G43: Low | H43: Active | I43: =IF(F43="","",F43-E43)
A44: 5043 | B44: Allocation | C44: EROS ELEVATORS & ESCALATORS PVT LTD | D44: Schedule | E44: 45748 | F44: 45778 | G44: Low | H44: Completed | I44: =IF(F44="","",F44-E44) -> 30
A45: 5044 | B45: Allocation | C45: ELECTROSTEEL CASTINGS LTD / ELECTROSTEEL GROUP | D45: Schedule | E45: 45748 | F45: 46140 | G45: Low | H45: Completed | I45: =IF(F45="","",F45-E45) -> 392
A46: 5045 | B46: Escalation | C46: SAI SANKET INDUSTRIES PVT.LTD | D46: Schedule | E46: 45748 | F46: 45802 | G46: Low | H46: Completed | I46: =IF(F46="","",F46-E46) -> 54
A47: 5046 | B47: Escalation | C47: LOTUS TEXCOM INDIA LLP | D47: Schedule | E47: 45751 | F47: 45861 | G47: Low | H47: Lost | I47: =IF(F47="","",F47-E47) -> 110
A48: 5047 | B48: Escalation | C48: BRILLIANT POLYMERS PVT. LTD | D48: Schedule | E48: 45761 | F48: 45809 | G48: Low | H48: Completed | I48: =IF(F48="","",F48-E48) -> 48
A49: 5048 | B49: Escalation | C49: AUTOTECH-SIRMAX INDIA PVT LTD | D49: Schedule | E49: 45768 | F49: 45855 | G49: Low | H49: Completed | I49: =IF(F49="","",F49-E49) -> 87
A50: 5049 | B50: Escalation | C50: TAO AUTOMATION SERVICES PVT LTD | D50: Schedule | E50: 45769 | F50: 45855 | G50: Low | H50: Completed | I50: =IF(F50="","",F50-E50) -> 86
A51: 5050 | B51: Escalation | C51: BASANT OVERSEAS | D51: Schedule | E51: 45772 | F51: 46111 | G51: Low | H51: Lost | I51: =IF(F51="","",F51-E51) -> 339
A52: 5051 | B52: Escalation | C52: POONAM ROLLER FLOUR MILLS PRIVATE LIMITED | D52: CR | E52: 45775 | F52: 45812 | G52: Low | H52: Lost | I52: =IF(F52="","",F52-E52) -> 37
A53: 5052 | B53: Allocation | C53: SNAPWORK TECHNOLOGIES PVT LTD | D53: Schedule | E53: 45780 | F53: 46080 | G53: Low | H53: Completed | I53: =IF(F53="","",F53-E53) -> 300
A54: 5053 | B54: Escalation | C54: Royal Chains Pvt. Ltd. and Royal Italian Jewelry Pvt. Ltd. | D54: CR | E54: 45801 | F54: 45861 | G54: Low | H54: Completed | I54: =IF(F54="","",F54-E54) -> 60
A55: 5054 | B55: Allocation | C55: BRIGHT BROTHERS LTD. / BRITE | D55: Schedule | E55: 45804 | F55: 46080 | G55: Low | H55: Completed | I55: =IF(F55="","",F55-E55) -> 276
... A91: 5090 | B91: Escalation | C91: ATHARVA FACILITY MANAGEMENT AND SECURITY | D91: Schedule | E91: 45917 | F91: 45958 | G91: Low | H91: Completed | I91: =IF(F91="","",F91-E91) -> 41
A92: 5091 | B92: Allocation | C92: MEDIPULSE HOSPITAL | D92: Schedule | E92: 45909 | G92: Low | H92: Active | I92: =IF(F92="","",F92-E92)
A93: 5092 | B93: Allocation | C93: PARADISE GROUP | D93: Schedule | E93: 45912 | G93: Low | H93: Active | I93: =IF(F93="","",F93-E93)
A94: 5093 | B94: Escalation | C94: DRS EARTHWORK PRIVATE LIMITED | D94: Schedule | E94: 45924 | F94: 45989 | G94: Low | H94: Completed | I94: =IF(F94="","",F94-E94) -> 65
A95: 5094 | B95: Allocation | C95: CENTRE FOR URBANIZATION BUILDINGS AND ENVIRONMENT (CUBE IITM) | D95: Schedule | E95: 45929 | F95: 46140 | G95: Low | H95: Lost | I95: =IF(F95="","",F95-E95) -> 211
A96: 5095 | B96: Escalation | C96: PISCES CONTAINER LINES INDIA PVT. LTD. | D96: Schedule | E96: 45943 | F96: 45958 | G96: Low | H96: Completed | I96: =IF(F96="","",F96-E96) -> 15
A97: 5096 | B97: Escalation | C97: AUROUS JEWELS LLP | D97: Schedule | E97: 45943 | F97: 45958 | G97: Low | H97: Completed | I97: =IF(F97="","",F97-E97) -> 15
A98: 5097 | B98: Allocation | C98: HARDCARB TECHNOLOGIES PVT. LTD. / VAUTID-SHAH HARDFACE PVT. LTD. - STAFF LICENSE | D98: Schedule | E98: 45938 | F98: 46140 | G98: Low | H98: Completed | I98: =IF(F98="","",F98-E98) -> 202
A99: 5098 | B99: Escalation | C99: RENMAKCH INDIA PVT. LTD. | D99: Schedule | E99: 45958 | F99: 46050 | G99: Low | H99: Completed | I99: =IF(F99="","",F99-E99) -> 92
A100: 5099 | B100: Escalation | C100: GNG ELECTRONICS LIMITED FACTORY | D100: Schedule | E100: 45943 | F100: 45958 | G100: Low | H100: Completed | I100: =IF(F100="","",F100-E100) -> 15
A101: 5100 | B101: Allocation | C101: WHISTLING WOODS INTERNATIONAL | D101: Schedule | E101: 45931 | G101: Low | H101: Active | I101: =IF(F101="","",F101-E101)
A102: 5101 | B102: Allocation | C102: VIVID ELECTROMECH LTD. / VIVID GROUP | D102: Schedule | E102: 45960 | F102: 46140 | G102: Low | H102: Completed | I102: =IF(F102="","",F102-E102) -> 180
A103: 5102 | B103: Allocation | C103: SREE METALIKS LTD | D103: Schedule | E103: 45972 | F103: 46140 | G103: Low | H103: Completed | I103: =IF(F103="","",F103-E103) -> 168
...

Sheet Quarterly Followup
A1: Followup Due This Month | B1: Followup Quarter | C1: Followup Month | D1: Suggested Followup Date | E1: Project Code | F1: Project Name | G1: Status | H1: Completed Date | I1: Client Interaction Date | J1: Current Usage Status | K1: Challenges / Pain Points | L1: Support Required | M1: Scope of UpSelling | N1: PM Followup Notes | O1: Next Followup Date
A2: No | B2: Q3 2026 | C2: July | D2: 46218 | E2: 5001 | F2: TARASAFE INTERNATIONAL PRIVATE LIMITED_STAFF | G2: Completed | H2: 45958 | N2: Check if the client is using the system properly, whether any challenge is open, and whether support/optimization is needed.
A3: No | B3: Q3 2026 | C3: September | D3: 46280 | E3: 5003 | F3: Maharashtra Book Manufacturing | G3: Completed | H3: 45772 | N3: Check if the client is using the system properly, whether any challenge is open, and whether support/optimization is needed.
A4: No | B4: Q3 2026 | C4: July | D4: 46218 | E4: 5004 | F4: PLASMA RESEARCH TRUST NX | G4: Completed | H4: 45772 | N4: Check if the client is using the system properly, whether any challenge is open, and whether support/optimization is needed.
A5: Yes | B5: Q3 2026 | C5: August | D5: 46249 | E5: 5005 | F5: Bengal Energy_Staff | G5: Completed | H5: 46111 | N5: Check if the client is using the system properly, whether any challenge is open, and whether support/optimization is needed.
A6: Yes | B6: Q3 2026 | C6: August | D6: 46249 | E6: 5008 | F6: Aquaair International Frieght Services | G6: Completed | H6: 45772 | N6: Check if the client is using the system properly, whether any challenge is open, and whether support/optimization is needed.
A7: No | B7: Q3 2026 | C7: September | D7: 46280 | E7: 5009 | F7: Hardcarb Technologies Private Limited | G7: Completed | H7: 45772 | N7: Check if the client is using the system properly, whether any challenge is open, and whether support/optimization is needed.
A8: No | B8: Q3 2026 | C8: July | D8: 46218 | E8: 5010 | F8: MADHUSUMAN ENTERPRISES (MSE) HVAC SERVICES INDIA | G8: Completed | H8: 45855 | N8: Check if the client is using the system properly, whether any challenge is open, and whether support/optimization is needed.
A9: Yes | B9: Q3 2026 | C9: August | D9: 46249 | E9: 5011 | F9: YUVA PARIVARTAN KHERWADI SOCIAL WELFARE ASSOCIATION | G9: Completed | H9: 45958 | N9: Check if the client is using the system properly, whether any challenge is open, and whether support/optimization is needed.
A10: No | B10: Q3 2026 | C10: September | D10: 46280 | E10: 5012 | F10: GCOM SYSTEMS AND SOLUTIONS (OUR LADY OF SALVATION) | G10: Completed | H10: 45772 | N10: Check if the client is using the system properly, whether any challenge is open, and whether support/optimization is needed.
A11: No | B11: Q3 2026 | C11: July | D11: 46218 | E11: 5013 | F11: Metafab | G11: Completed | H11: 45772 | N11: Check if the client is using the system properly, whether any challenge is open, and whether support/optimization is needed.
A12: Yes | B12: Q3 2026 | C12: August | D12: 46249 | E12: 5014 | F12: Texple | G12: Completed | H12: 45772 | N12: Check if the client is using the system properly, whether any challenge is open, and whether support/optimization is needed.
A13: No | B13: Q3 2026 | C13: September | D13: 46280 | E13: 5015 | F13: ERMELLI PRIVATE LIMITED | G13: Completed | H13: 45772 | N13: Check if the client is using the system properly, whether any challenge is open, and whether support/optimization is needed.
... A114: No | B114: Q3 2026 | C114: September | D114: 46280 | E114: 5165 | F114: Navio Shipping | G114: Completed | H114: 46245 | N114: Check if the client is using the system properly, whether any challenge is open, and whether support/optimization is needed.
